Workbook
Name T_S: 물성DB!$A$6:$A$12
Name V_S: 물성DB!$B$6:$B$12
Name T_SY: 물성DB!$D$6:$D$9
Name V_SY: 물성DB!$E$6:$E$9
Name T_E: 물성DB!$G$6:$G$9
Name V_E: 물성DB!$H$6:$H$9
Name BucklingT: 좌굴스캔!$A$2:$A$200
Name BucklingOK: 좌굴스캔!$F$2:$F$200

Sheet 계산기
B1: PFHE Plain 핀 적정두께 계산기 (ALPEMA 2024 기반 유도)
B2: 예비설계용 · 단위 MPa/mm · 파랑=입력 셀 · 인증설계는 ALPEMA 5.15.1.1(승인 계산법)/5.15.1.2(파열시험)에 따름
B3: =IF($C$5>204,"⚠️ 설계온도 204°C 초과 — 3003 재질한계(ALPEMA Table 6-1) 벗어남. 결과 무효!","")
B4: ① 입력 (파랑 셀을 편집)
B5: 설계온도 T | C5: 65 | D5: °C | E5: ≤ 204 (3003 재질한계)
B6: 핀 인장 유발 차압 ΔP_t | C6: 5 | D6: MPa | E6: 통상 = 층 설계압력(MAWP)
B7: 핀 압축 유발 차압 ΔP_c | C7: 0.6 | D7: MPa | E7: 인접층 고압/자층 감압 시 (없으면 0)
B8: 자층 핀 피치 p | C8: 1.4 | D8: mm | E8: ALPEMA 1.0–4.5
B9: 인접층 핀 피치 p_adj | C9: 0 | D9: mm | E9: 0=자층과 동일. 파팅시트 스팬용
B10: 핀 높이 h | C10: 6.5 | D10: mm | E10: ALPEMA 2.0–12
B11: 좌굴 유효길이계수 K | C11: 0.7 | D11: - | E11: 기본 0.7, 구속 불확실 시 1.0
B12: 인장 스테이 계수 f | C12: 1 | D12: - | E12: UG-50(b) 준용 시 1.10
B13: 제작 공차계수 | C13: 1 | D13: - | E13: 0<f≤1 (예 0.9=공칭의 90%만 유효)
B14: 파팅시트 차압 w=|P_A−P_B| | C14: 5 | D14: MPa | E14: 층간 순차압
B15: 균형가압 P_min | C15: 5 | D15: MPa | E15: 양면 동시가압 낮은쪽(핀 어긋남 항)
B16: 선정 핀 두께(공칭) t_sel | C16: 0.3 | D16: mm | E16: 검증용. 0이면 검증 생략
B17: ② 상수 및 온도별 물성 (자동)
B18: 포아송비 ν | C18: 0.33 | D18: - | E18: 알루미늄
B19: 좌굴 설계계수 DF | C19: 3 | D19: - | E19: ASME UG-28 준용
B21: 허용응력 S(T) | C21: =IF($C$5<=MIN(T_S),INDEX(V_S,1),IF($C$5>=MAX(T_S),INDEX(V_S,COUNT(T_S)),INDEX(V_S,MATCH($C$5,T_S,1))+($C$5-INDEX(T_S,MATCH($C$5,T_S,1)))/(INDEX(T_S,MATCH($C$5,T_S,1)+1)-INDEX(T_S,MATCH($C$5,T_S,1)))*(INDEX(V_S,MATCH($C$5,T_S,1)+1)-INDEX(V_S,MATCH($C$5,T_S,1))))) | D21: MPa | E21: 3003-O, 온도 선형보간
B22: 항복강도 Sy(T) | C22: =IF($C$5<=MIN(T_SY),INDEX(V_SY,1),IF($C$5>=MAX(T_SY),INDEX(V_SY,COUNT(T_SY)),INDEX(V_SY,MATCH($C$5,T_SY,1))+($C$5-INDEX(T_SY,MATCH($C$5,T_SY,1)))/(INDEX(T_SY,MATCH($C$5,T_SY,1)+1)-INDEX(T_SY,MATCH($C$5,T_SY,1)))*(INDEX(V_SY,MATCH($C$5,T_SY,1)+1)-INDEX(V_SY,MATCH($C$5,T_SY,1))))) | D22: MPa | E22: Johnson 좌굴 천이용
B23: 탄성계수 E(T) | C23: =IF($C$5<=MIN(T_E),INDEX(V_E,1),IF($C$5>=MAX(T_E),INDEX(V_E,COUNT(T_E)),INDEX(V_E,MATCH($C$5,T_E,1))+($C$5-INDEX(T_E,MATCH($C$5,T_E,1)))/(INDEX(T_E,MATCH($C$5,T_E,1)+1)-INDEX(T_E,MATCH($C$5,T_E,1)))*(INDEX(V_E,MATCH($C$5,T_E,1)+1)-INDEX(V_E,MATCH($C$5,T_E,1))))) | D23: MPa | E23: 좌굴 임계응력용
B24: 온도 유효성 | C24: =IF($C$5>204,"온도초과(>204°C)","OK") | D24: - | E24: 204°C 초과 시 결과 무효
B25: ③ 결과 — 핀 최소두께
B26: [1] 핀 인장 최소두께 (식2) | C26: =IF($C$6<=0,0,$C$12*$C$6*$C$8/($C$21+$C$12*$C$6)) | D26: mm | E26: t ≥ f·ΔP_t·p/(S+f·ΔP_t)
B27: [2] 핀 좌굴 최소두께 (식3~5) | C27: =IF($C$7<=0,0,IF(COUNTIF(BucklingOK,1)=0,999,_xlfn.MINIFS(BucklingT,BucklingOK,1))) | D27: mm | E27: =IF(AND($C$7>0,COUNTIF(BucklingOK,1)=0),"⚠️ 좌굴 소요두께 1.0mm 초과 — 표준 핀 불가","Johnson 천이·전피치 하중폭 (좌굴스캔 시트)")
B28: [3] 요구 핀두께 (유효) | C28: =MAX($C$26,$C$27) | D28: mm | E28: max(인장, 좌굴)
B29: 요구 핀두께 (공칭) | C29: =IF($C$5>204,"온도초과",$C$28/$C$13) | D29: mm | E29: 유효 / 공차계수
B30: ALPEMA 두께범위 판정 | C30: =IF($C$5>204,"—",IF(AND($C$29>=0.15,$C$29<=0.7),"OK 범위내","⚠️ 범위밖(0.15-0.7)")) | D30: - | E30: 제작 가능 범위 0.15–0.7 mm
B31: 핀 피치 판정 | C31: =IF(AND($C$8>=1,$C$8<=4.5),"OK 범위내","⚠️ 범위밖(1.0-4.5)") | D31: - | E31: ALPEMA 5.11.4
B32: 핀 높이 판정 | C32: =IF(AND($C$10>=2,$C$10<=12),"OK 범위내","⚠️ 범위밖(2-12)") | D32: - | E32: ALPEMA 5.11.4
B33: ④ 파팅시트 두께 (식6~7)
B34: 지배 피치 p̄ | C34: =IF($C$9>0,MAX($C$8,$C$9),$C$8) | D34: mm | E34: max(자층, 인접층 피치)
B35: 스팬 공제 핀두께 t_fin,eff | C35: =IF($C$9>$C$8,0,IF($C$16>0,$C$16*$C$13,$C$28)) | D35: mm | E35: 인접층 지배 시 0(보수) — 문서 §6.1
B36: 스팬 s | C36: =$C$34-$C$35 | D36: mm | E36: s = p̄ − t_fin,eff
B37: 설계 모멘트 M_d | C37: =$C$14*$C$36^2/12+$C$15*($C$34-$C$35)*$C$34/8 | D37: N·mm/mm | E37: w·s²/12 + P_min·(p̄−t)·p̄/8
B38: 파팅시트 최소두께 t_ps | C38: =IF($C$36<=0,"스팬오류",SQRT(4*$C$37/$C$21)) | D38: mm | E38: σ_b ≤ 1.5·S
B39: ALPEMA 시트범위 판정 | C39: =IF(NOT(ISNUMBER($C$38)),"—",IF($C$38>2,"⚠️ 범위밖(>2.0)",IF($C$38<0.8,"소요<0.8 → 표준 0.8 적용","OK 범위내"))) | D39: - | E39: ALPEMA 5.11.1: 0.8–2.0 mm
B40: ⑤ 선정 두께 검증 (t_sel 입력 시)
B41: 유효 핀두께 t_eff | C41: =IF($C$16>0,$C$16*$C$13,"") | D41: mm | E41: 공칭 × 공차계수
...

Sheet 물성DB
A1: 재료 물성 데이터 — AL 3003-O (ASME Sec. II-D 대표값)
A2: ⚠️ 대표값 — 실제 설계 전 적용 코드 연도판 값으로 교체할 것. 온도 오름차순 유지.
A4: 허용응력 S(T) | D4: 항복강도 Sy(T) | G4: 탄성계수 E(T)
A5: 온도(°C) | B5: S (MPa) | D5: 온도(°C) | E5: Sy (MPa) | G5: 온도(°C) | H5: E (MPa)
A6: 40 | B6: 22.8 | D6: 40 | E6: 34.5 | G6: 25 | H6: 68900
A7: 65 | B7: 22.8 | D7: 93 | E7: 33.1 | G7: 93 | H7: 66200
A8: 93 | B8: 22.6 | D8: 149 | E8: 29.6 | G8: 149 | H8: 63400
A9: 121 | B9: 21.4 | D9: 204 | E9: 24.1 | G9: 204 | H9: 60000
A10: 149 | B10: 18.6
A11: 177 | B11: 14.5
A12: 204 | B12: 11

Sheet 좌굴스캔
A1: t 후보(mm) | B1: σ_c(MPa) | C1: σ_cr,E(MPa) | D1: σ_cr Johnson(MPa) | E1: 허용(MPa) | F1: OK(1/0) | H1: 핀 좌굴 최소두께 = ΔP_c>0 일 때 OK=1 인 최소 t 후보 (계산기!C27, MINIFS)
A2: 0.01 | B2: =계산기!$C$7*계산기!$C$8/A2 | C2: =PI()^2*계산기!$C$23/(12*(1-계산기!$C$18^2))*(A2/(계산기!$C$11*계산기!$C$10))^2 | D2: =IF(C2<=계산기!$C$22/2,C2,계산기!$C$22*(1-계산기!$C$22/(4*C2))) | E2: =MIN(D2/계산기!$C$19,계산기!$C$21) | F2: =IF(B2<=E2,1,0)
A3: 0.015 | B3: =계산기!$C$7*계산기!$C$8/A3 | C3: =PI()^2*계산기!$C$23/(12*(1-계산기!$C$18^2))*(A3/(계산기!$C$11*계산기!$C$10))^2 | D3: =IF(C3<=계산기!$C$22/2,C3,계산기!$C$22*(1-계산기!$C$22/(4*C3))) | E3: =MIN(D3/계산기!$C$19,계산기!$C$21) | F3: =IF(B3<=E3,1,0)
A4: 0.02 | B4: =계산기!$C$7*계산기!$C$8/A4 | C4: =PI()^2*계산기!$C$23/(12*(1-계산기!$C$18^2))*(A4/(계산기!$C$11*계산기!$C$10))^2 | D4: =IF(C4<=계산기!$C$22/2,C4,계산기!$C$22*(1-계산기!$C$22/(4*C4))) | E4: =MIN(D4/계산기!$C$19,계산기!$C$21) | F4: =IF(B4<=E4,1,0)
A5: 0.025 | B5: =계산기!$C$7*계산기!$C$8/A5 | C5: =PI()^2*계산기!$C$23/(12*(1-계산기!$C$18^2))*(A5/(계산기!$C$11*계산기!$C$10))^2 | D5: =IF(C5<=계산기!$C$22/2,C5,계산기!$C$22*(1-계산기!$C$22/(4*C5))) | E5: =MIN(D5/계산기!$C$19,계산기!$C$21) | F5: =IF(B5<=E5,1,0)
A6: 0.03 | B6: =계산기!$C$7*계산기!$C$8/A6 | C6: =PI()^2*계산기!$C$23/(12*(1-계산기!$C$18^2))*(A6/(계산기!$C$11*계산기!$C$10))^2 | D6: =IF(C6<=계산기!$C$22/2,C6,계산기!$C$22*(1-계산기!$C$22/(4*C6))) | E6: =MIN(D6/계산기!$C$19,계산기!$C$21) | F6: =IF(B6<=E6,1,0)
A7: 0.035 | B7: =계산기!$C$7*계산기!$C$8/A7 | C7: =PI()^2*계산기!$C$23/(12*(1-계산기!$C$18^2))*(A7/(계산기!$C$11*계산기!$C$10))^2 | D7: =IF(C7<=계산기!$C$22/2,C7,계산기!$C$22*(1-계산기!$C$22/(4*C7))) | E7: =MIN(D7/계산기!$C$19,계산기!$C$21) | F7: =IF(B7<=E7,1,0)
A8: 0.04 | B8: =계산기!$C$7*계산기!$C$8/A8 | C8: =PI()^2*계산기!$C$23/(12*(1-계산기!$C$18^2))*(A8/(계산기!$C$11*계산기!$C$10))^2 | D8: =IF(C8<=계산기!$C$22/2,C8,계산기!$C$22*(1-계산기!$C$22/(4*C8))) | E8: =MIN(D8/계산기!$C$19,계산기!$C$21) | F8: =IF(B8<=E8,1,0)
A9: 0.045 | B9: =계산기!$C$7*계산기!$C$8/A9 | C9: =PI()^2*계산기!$C$23/(12*(1-계산기!$C$18^2))*(A9/(계산기!$C$11*계산기!$C$10))^2 | D9: =IF(C9<=계산기!$C$22/2,C9,계산기!$C$22*(1-계산기!$C$22/(4*C9))) | E9: =MIN(D9/계산기!$C$19,계산기!$C$21) | F9: =IF(B9<=E9,1,0)
A10: 0.05 | B10: =계산기!$C$7*계산기!$C$8/A10 | C10: =PI()^2*계산기!$C$23/(12*(1-계산기!$C$18^2))*(A10/(계산기!$C$11*계산기!$C$10))^2 | D10: =IF(C10<=계산기!$C$22/2,C10,계산기!$C$22*(1-계산기!$C$22/(4*C10))) | E10: =MIN(D10/계산기!$C$19,계산기!$C$21) | F10: =IF(B10<=E10,1,0)
A11: 0.055 | B11: =계산기!$C$7*계산기!$C$8/A11 | C11: =PI()^2*계산기!$C$23/(12*(1-계산기!$C$18^2))*(A11/(계산기!$C$11*계산기!$C$10))^2 | D11: =IF(C11<=계산기!$C$22/2,C11,계산기!$C$22*(1-계산기!$C$22/(4*C11))) | E11: =MIN(D11/계산기!$C$19,계산기!$C$21) | F11: =IF(B11<=E11,1,0)
A12: 0.06 | B12: =계산기!$C$7*계산기!$C$8/A12 | C12: =PI()^2*계산기!$C$23/(12*(1-계산기!$C$18^2))*(A12/(계산기!$C$11*계산기!$C$10))^2 | D12: =IF(C12<=계산기!$C$22/2,C12,계산기!$C$22*(1-계산기!$C$22/(4*C12))) | E12: =MIN(D12/계산기!$C$19,계산기!$C$21) | F12: =IF(B12<=E12,1,0)
A13: 0.065 | B13: =계산기!$C$7*계산기!$C$8/A13 | C13: =PI()^2*계산기!$C$23/(12*(1-계산기!$C$18^2))*(A13/(계산기!$C$11*계산기!$C$10))^2 | D13: =IF(C13<=계산기!$C$22/2,C13,계산기!$C$22*(1-계산기!$C$22/(4*C13))) | E13: =MIN(D13/계산기!$C$19,계산기!$C$21) | F13: =IF(B13<=E13,1,0)
... A200: 1 | B200: =계산기!$C$7*계산기!$C$8/A200 | C200: =PI()^2*계산기!$C$23/(12*(1-계산기!$C$18^2))*(A200/(계산기!$C$11*계산기!$C$10))^2 | D200: =IF(C200<=계산기!$C$22/2,C200,계산기!$C$22*(1-계산기!$C$22/(4*C200))) | E200: =MIN(D200/계산기!$C$19,계산기!$C$21) | F200: =IF(B200<=E200,1,0)

Sheet 설명
A1: PFHE Plain 핀 적정두께 계산기 — 사용 안내
A3: ■ 사용법
A4: 1. [계산기] 시트의 파랑(노랑배경) 셀만 편집합니다. 나머지는 자동 계산 수식입니다.
A5: 2. 단위는 압력 MPa, 길이 mm 입니다 (1 MPa = 10 bar ≈ 10.2 kgf/cm²).
A6: 3. [1][2]는 최소 소요두께, [3]은 채택 기준(둘 중 큰 값)입니다.
A7: 4. t_sel(선정 두께)을 입력하면 ⑤ 검증에서 합/부를 판정합니다. 0이면 검증을 건너뜁니다.
A8: 5. ΔP_c(압축)가 0이면 좌굴 검토는 생략됩니다.
A10: ■ 계산 근거 (수식)
A11: [1] 핀 인장: t ≥ f·ΔP_t·p / (S(T) + f·ΔP_t)
A12: [2] 핀 좌굴: ΔP_c·p/t ≤ min(σ_cr/DF, S), σ_cr는 오일러식 + Johnson 비탄성 천이
A13: → [좌굴스캔] 시트가 후보 두께를 훑어 조건을 만족하는 최소 t를 MINIFS로 반환
A14: [3] 파팅시트: t_ps ≥ √(4·M_d/S), M_d = w·s²/12 + P_min·(p̄−t)·p̄/8
... A27: · 상세 유도는 fin_thickness_derivation.md, 원본 로직은 fin_thickness_calc.py 참조.
